[0m16:21:15.729695 [debug] [MainThread]: Sending event: {'category': 'dbt', 'action': 'invocation', 'label': 'start', 'context': [<snowplow_tracker.self_describing_json.SelfDescribingJson object at 0x000001859C54DC70>, <snowplow_tracker.self_describing_json.SelfDescribingJson object at 0x0000018599CDCC50>, <snowplow_tracker.self_describing_json.SelfDescribingJson object at 0x000001859C276F00>]}


============================== 16:21:15.736382 | 5b66e146-1a72-459b-8557-34dde1f27893 ==============================
[0m16:21:15.736382 [info ] [MainThread]: Running with dbt=1.9.2
[0m16:21:15.737380 [debug] [MainThread]: running dbt with arguments {'printer_width': '80', 'indirect_selection': 'eager', 'write_json': 'True', 'log_cache_events': 'False', 'partial_parse': 'True', 'cache_selected_only': 'False', 'profiles_dir': 'C:\\Users\\mathe\\.dbt', 'debug': 'False', 'version_check': 'True', 'log_path': 'logs', 'warn_error': 'None', 'fail_fast': 'False', 'use_colors': 'True', 'use_experimental_parser': 'False', 'empty': 'None', 'quiet': 'False', 'no_print': 'None', 'warn_error_options': 'WarnErrorOptions(include=[], exclude=[])', 'invocation_command': 'dbt init', 'log_format': 'default', 'introspect': 'True', 'target_path': 'None', 'static_parser': 'True', 'send_anonymous_usage_stats': 'True'}
[0m16:21:23.184175 [debug] [MainThread]: Starter project path: C:\Users\mathe\AppData\Local\Programs\Python\Python312\Lib\site-packages\dbt\include\starter_project
[0m16:21:23.364496 [info ] [MainThread]: 
Your new dbt project "db_desafio" was created!

For more information on how to configure the profiles.yml file,
please consult the dbt documentation here:

  https://docs.getdbt.com/docs/configure-your-profile

One more thing:

Need help? Don't hesitate to reach out to us via GitHub issues or on Slack:

  https://community.getdbt.com/

Happy modeling!

[0m16:21:23.370446 [info ] [MainThread]: Setting up your profile.
[0m16:26:42.164281 [debug] [MainThread]: Command `dbt init` succeeded at 16:26:42.164281 after 327.03 seconds
[0m16:26:42.164281 [debug] [MainThread]: Sending event: {'category': 'dbt', 'action': 'invocation', 'label': 'end', 'context': [<snowplow_tracker.self_describing_json.SelfDescribingJson object at 0x000001859BBE7620>, <snowplow_tracker.self_describing_json.SelfDescribingJson object at 0x000001859C276F00>, <snowplow_tracker.self_describing_json.SelfDescribingJson object at 0x000001859C8A33B0>]}
[0m16:26:42.169800 [debug] [MainThread]: Flushing usage events
[0m16:26:42.822798 [debug] [MainThread]: An error was encountered while trying to flush usage events
[0m16:27:25.262204 [debug] [MainThread]: Sending event: {'category': 'dbt', 'action': 'invocation', 'label': 'start', 'context': [<snowplow_tracker.self_describing_json.SelfDescribingJson object at 0x000002055115CCE0>, <snowplow_tracker.self_describing_json.SelfDescribingJson object at 0x00000205515EA0F0>, <snowplow_tracker.self_describing_json.SelfDescribingJson object at 0x0000020553D84710>]}


============================== 16:27:25.267894 | 2bf1e4c1-d575-4257-a59f-fbaefbcfd86b ==============================
[0m16:27:25.267894 [info ] [MainThread]: Running with dbt=1.9.2
[0m16:27:25.273295 [debug] [MainThread]: running dbt with arguments {'printer_width': '80', 'indirect_selection': 'eager', 'write_json': 'True', 'log_cache_events': 'False', 'partial_parse': 'True', 'cache_selected_only': 'False', 'profiles_dir': 'C:\\Users\\mathe\\.dbt', 'version_check': 'True', 'debug': 'False', 'log_path': 'logs', 'fail_fast': 'False', 'warn_error': 'None', 'use_colors': 'True', 'use_experimental_parser': 'False', 'no_print': 'None', 'quiet': 'False', 'empty': 'None', 'warn_error_options': 'WarnErrorOptions(include=[], exclude=[])', 'static_parser': 'True', 'introspect': 'True', 'log_format': 'default', 'target_path': 'None', 'invocation_command': 'dbt seed', 'send_anonymous_usage_stats': 'True'}
[0m16:27:25.274291 [error] [MainThread]: Encountered an error:
Runtime Error
  No dbt_project.yml found at expected path C:\Users\mathe\OneDrive\Documentos\Git Repos\Desafio_DIT_DataScience\dbt_project.yml
  Verify that each entry within packages.yml (and their transitive dependencies) contains a file named dbt_project.yml
  
[0m16:27:25.278006 [debug] [MainThread]: Command `dbt seed` failed at 16:27:25.277010 after 0.66 seconds
[0m16:27:25.278006 [debug] [MainThread]: Sending event: {'category': 'dbt', 'action': 'invocation', 'label': 'end', 'context': [<snowplow_tracker.self_describing_json.SelfDescribingJson object at 0x0000020553293080>, <snowplow_tracker.self_describing_json.SelfDescribingJson object at 0x000002055115CCE0>, <snowplow_tracker.self_describing_json.SelfDescribingJson object at 0x00000205532FB6E0>]}
[0m16:27:25.278006 [debug] [MainThread]: Flushing usage events
[0m16:27:25.817583 [debug] [MainThread]: An error was encountered while trying to flush usage events
[0m17:12:49.983988 [debug] [MainThread]: Sending event: {'category': 'dbt', 'action': 'invocation', 'label': 'start', 'context': [<snowplow_tracker.self_describing_json.SelfDescribingJson object at 0x0000018A1BCE6600>, <snowplow_tracker.self_describing_json.SelfDescribingJson object at 0x0000018A17E7D9D0>, <snowplow_tracker.self_describing_json.SelfDescribingJson object at 0x0000018A1BCE6900>]}


============================== 17:12:49.992897 | f84b1d20-a5c9-4b0e-b347-b44d3a401849 ==============================
[0m17:12:49.992897 [info ] [MainThread]: Running with dbt=1.9.2
[0m17:12:49.997365 [debug] [MainThread]: running dbt with arguments {'printer_width': '80', 'indirect_selection': 'eager', 'write_json': 'True', 'log_cache_events': 'False', 'partial_parse': 'True', 'cache_selected_only': 'False', 'warn_error': 'None', 'debug': 'False', 'profiles_dir': 'C:\\Users\\mathe\\.dbt', 'log_path': 'logs', 'version_check': 'True', 'fail_fast': 'False', 'use_colors': 'True', 'use_experimental_parser': 'False', 'no_print': 'None', 'quiet': 'False', 'empty': 'None', 'log_format': 'default', 'introspect': 'True', 'invocation_command': 'dbt seed', 'static_parser': 'True', 'target_path': 'None', 'warn_error_options': 'WarnErrorOptions(include=[], exclude=[])', 'send_anonymous_usage_stats': 'True'}
[0m17:12:49.999331 [error] [MainThread]: Encountered an error:
Runtime Error
  No dbt_project.yml found at expected path C:\Users\mathe\OneDrive\Documentos\Git Repos\Desafio_DIT_DataScience\dbt_project.yml
  Verify that each entry within packages.yml (and their transitive dependencies) contains a file named dbt_project.yml
  
[0m17:12:50.002785 [debug] [MainThread]: Command `dbt seed` failed at 17:12:50.002785 after 0.64 seconds
[0m17:12:50.002785 [debug] [MainThread]: Sending event: {'category': 'dbt', 'action': 'invocation', 'label': 'end', 'context': [<snowplow_tracker.self_describing_json.SelfDescribingJson object at 0x0000018A1B368740>, <snowplow_tracker.self_describing_json.SelfDescribingJson object at 0x0000018A1B84F4D0>, <snowplow_tracker.self_describing_json.SelfDescribingJson object at 0x0000018A1BCE6600>]}
[0m17:12:50.002785 [debug] [MainThread]: Flushing usage events
[0m17:12:50.695843 [debug] [MainThread]: An error was encountered while trying to flush usage events
